Workbook

Sheet Criteria
A1: Screen | B1: ID | C1: Criterion | D1: Threshold | E1: Type | F1: Why it's there (investor rationale) | G1: What it adds to the thesis | H1: Verifiable now? | I1: Why not easy / caveat
A2: Core Compounders | B2: U | C2: Universe | D2: No funds/SPACs/REITs/shells; excludes banks, insurers, real estate, commodity producers, autos, airlines, telecom, utilities, media, ad agencies | E2: Universe | F2: Chris Hohn states that leaving out banks, airlines, wireless telecom, media and ad agencies means avoiding what he calls bad businesses, because they face heavy competition or, for banks, high leverage, so profits are fragile. A mentioned example: air travel grew about 5% a year for a century, yet airlines collectively made minimal profits. Pat Dorsey states that excluding industries like airlines, auto parts, life insurance and oil and gas means avoiding price takers, because a large part of their future is not under their control. No specific past example given. Terry Smith states that dropping low-return sectors makes sense because good-company sectors don't become bad ones and vice versa; low-return industries stay low. A mentioned example: the airline industry, which he says never makes an adequate return on capital. | G2: Only businesses that can have pricing power. | H2: Easy | I2: Uses SEC industry (SIC) code; codes can be coarse or outdated (manual override list exists).
A3: Core Compounders | B3: G1 | C3: History | D3: >= 8 years of data | E3: Data | F3: Dev Kantesaria states that a long record matters because a company only meets his bar for predictability if he is confident it stays dominant for at least the next 10 years, and he prefers business models that have already worked for decades. No specific past example given. Chris Hohn states that a long history is informative because "good companies stay good and bad companies stay bad": barriers to entry persist, though only if you judged quality right in the first place. No specific past example given. | G3: Proves durability. | H3: Easy
A4: Core Compounders | B4: G2 | C4: Recent report | D4: Last annual report <= 1.6 years old | E4: Data | F4: No investor source: old financial statements can hide a recent collapse, so the latest annual report must be current. | G4: Keeps the screen current. | H4: Easy | I4: Rare: some foreign (20-F) reports filed but not yet in SEC XBRL data -> flagged.
A5: Core Compounders | B5: G3 | C5: Size (revenue) | D5: Revenue >= $200M | E5: Size | F5: No investor source: very small filers have patchier data and are harder to own in meaningful size. | G5: Focus on established businesses. | H5: Easy
A6: Core Compounders | B6: G4 | C6: Consistent profits | D6: <= 1 operating-loss year in 10 | E6: Quality | F6: Dev Kantesaria states that steady profits signal predictability, which he will not give up, because he hates losing money and avoids anything that "could go down 90% tomorrow"; quality means growth and predictability together. A mentioned example: young software firms are too unpredictable, while Nestlé or Hershey are predictable but too slow. | G6: Predictability. | H6: Easy
A7: Core Compounders | B7: G5a | C7: High returns (median) | D7: 10-yr median ROIC >= 15% | E7: Quality | F7: Pat Dorsey states that a high return on capital for many years is the sign of a moat, because Morningstar's moat work started by studying every company earning over 15% on capital for over 15 years (numbers he calls arbitrary). He warns ROIC can mislead where investment is expensed. No specific past example given. Terry Smith states that a high return on capital is "the single most important thing", because over a long hold your return converges on what the business earns. A mentioned example: Munger's point that a business earning 6% on capital for 40 years returns about 6% even if bought at a huge discount. | G7: Moat evidence (core of the thesis). | H7: Easy | I7: Rare: debt in non-standard tags or D&A untagged -> flagged.
A8: Core Compounders | B8: G5b | C8: High returns (consistency) | D8: >= 80% of years with ROIC >= 10% | E8: Quality | F8: Terry Smith states that returns held year after year signal lasting quality, because "Good companies don't become bad companies by and large or vice versa". A mentioned example: in data back to 1966, high-ROE companies stayed clustered around 20%, still well above the low-return group decades later. Pat Dorsey states that returns that keep holding up show a moat at work, because a moat lengthens the time before returns on capital decline to the cost of capital, so the company can keep reinvesting at high rates. No specific past example given. | G8: Moat is persistent, not a spike. | H8: Easy
A9: Core Compounders | B9: G6 | C9: Growth | D9: 10-yr revenue CAGR >= 5% | E9: Growth | F9: Dev Kantesaria states that growth is half of quality, because a predictable company growing only 2-3% a year does not deliver strong long-term returns; he wants faster growth that is still predictable. A mentioned example: Nestlé and Hershey, which he calls extremely predictable but slow-growing. Pat Dorsey states that a reinvestment runway matters, because a company with an obvious place to put its cash is less likely to make a dumb acquisition or a badly timed buyback. A mentioned example: eBay, a great network-effect moat that ran out of room to grow once it had its market. Terry Smith states that growth is needed to reinvest cash at high returns, because high returns are wasted if the company is "landlocked" in a small niche or geography. No specific past example given. | G9: Runway to reinvest. | H9: Easy | I9: Rare: tag changes cause fake revenue jumps -> flagged.
A10: Core Compounders | B10: G7 | C10: Cash conversion | D10: FCF / net income >= 0.8 | E10: Quality | F10: Terry Smith states that profits must turn into cash, because his first test of a good company is a high return on capital in cash: cash delivered in a period divided by capital employed. A mentioned example: he put his own portfolio at about 25% on this measure (2022). Connor Haley states that free cash flow is a better guide than reported profits, because earnings and EBITDA "can be easily manipulated". No specific past example given. | G10: Earnings quality. | H10: Easy | I10: Rare: capex not in a standard tag -> estimated or flagged.
A11: Core Compounders | B11: G8 | C11: Balance sheet | D11: Net debt / operating cash flow <= 3x | E11: Safety | F11: Mala Gaonkar states that low debt matters because decent businesses she owned that were overlevered had much less room to maneuver when macro stress arrived; avoiding balance-sheet leverage, such as public LBOs, is one of her hard-learned lessons. A mentioned example: she names one such holding, spelled "Altis" in the captions, without further detail. Paul Singer states that surviving comes first, because big losses wreck judgment while intact capital lets you act in a crisis: "you make a buck you keep it". A mentioned example: he lost 88% of his parents' money on margin in 1974; in late 2008, "everything got cheap" for those with capital left. | G11: Survival / downside protection. | H11: Easy | I11: Rare: debt in non-standard tags or D&A untagged -> flagged.
A12: Core Compounders | B12: Flag | C12: Margin collapse | D12: TTM operating margin < half its 10-yr median | E12: Warning | F12: Pat Dorsey states that a moat shows up as returns that take a long time to fall to the cost of capital, so a sharp margin drop can mean the moat is weakening; but he warns margins can also fall because investment like sales and software development is expensed. No specific past example given. | G12: Stops buying a broken compounder. | H12: No | I12: Detected automatically; temporary vs permanent needs a human.
A13: Core Compounders | B13: Flag | C13: Revenue shrinking | D13: 3-yr revenue CAGR < 0 | E13: Warning | F13: Terry Smith states that shrinking revenue must be judged across the cycle, because he wants secular, not cyclical, growth: each peak and trough should be bigger than the last, though growth needn't come every year. No specific past example given. Dev Kantesaria states that a volume drop is acceptable only if it is temporary, because a toll collector keeps raising prices and earns more when volume returns, while pricing to hide secular volume decline can backfire. A mentioned example: FICO's mortgage-score volume fell for years while it raised those prices 100% one year and over 40% the next. | G13: Same. | H13: No | I13: Detected automatically; temporary vs permanent needs a human.
A14: Core Compounders | B14: Flag | C14: Lost money in 2008-09 | D14: Operating loss on falling sales in 2008-09 | E14: Warning | F14: Terry Smith states that a recession loss may expose cyclical rather than secular growth, because a real compounder's trough should still be bigger than its previous trough. No specific past example given. Stanley Druckenmiller states that profits holding up in a recession mean the stock is protected, because "if you have very good earnings in a recession and they're sustainable" the market eventually sees it. A mentioned example: in June 2023 he argued that if staples can rise in a recession, Nvidia could too, with orders and earnings up about 70% in a hard landing. | G14: Avoids mistaking a cycle for a moat. | H14: No | I14: Detected automatically; temporary vs permanent needs a human.
A15: Core Compounders | B15: V | C15: Valuation | D15: None (price-blind by design); P/E, EV/EBITDA, FCF yield and peer medians shown only | E15: Valuation | F15: Terry Smith states that judging quality before price is right, because investors spend almost all their effort on whether a stock is cheap and far too little on whether the business is high-grade, and long-run returns follow the business. A mentioned example: Munger's point that a business earning 18% on capital for 20-30 years wins even at an expensive-looking price. Dev Kantesaria states that price should not decide inclusion, because a great compounder's value growth overcomes overpaying by 10 or 15%, and precise valuation is "a silly exercise". A mentioned example: he bought S&P Global at $17.50 during the financial crisis; it is now over $500, compounding he says he never could have expected. | G15: Keeps great businesses on the list even when dear. | H15: n/a | I15: No 'cheap enough' test - see Valuation sheet.
A16: Core Compounders | B16: J | C16: Human / AI review | D16: Moat durability, switching costs, management and capital allocation, AI disruption, why mispriced | E16: Judgment | F16: Pat Dorsey states that moat durability needs human judgment, because "you can't screen for switching costs"; whether customers find it hard to switch is learned by talking to customers, ex-employees and salespeople. No specific past example given. Peter Thiel states that durability, not growth, drives most of a company's value, because growth is easy to measure today while whether a company still exists in a decade is hard to quantify. A mentioned example: about three-quarters of PayPal's value as of 2001 came from cash flows in 2011 and beyond. Connor Haley states that the review must ask why the stock might be mispriced, "the most important question in the investment process", because smart analysts with the same information usually price a stock fairly. No specific past example given. | G16: Decides whether the numbers reflect a real thesis. | H16: No | I16: Qualitative; not in financial data. Left to the AI review + you.
A17: Emerging Compounders | B17: U | C17: Universe | D17: Core universe, also minus commodity materials (chemicals, paper, building materials, non-metal mining) | E17: Universe | F17: Connor Haley states that leaving out commodity sectors means searching where lasting advantages are more common, because his team found energy, materials and financials rarely contain many businesses with real competitive edges. A mentioned example: Alta Fox's study of 104 multibaggers (2015-2020) excluded energy, materials and financials from the start. Terry Smith states that avoiding materials means avoiding a sector with persistently low returns, because returns on capital stay in place for decades and a low price does not turn a bad company into a good one. A mentioned example: in his sector data, materials sat with utilities, telecoms, transport, energy and retailing among the persistently low-return groups. | G17: Only potential niche winners. | H17: Easy | I17: Uses SEC industry (SIC) code; codes can be coarse or outdated (manual override list exists).
A18: Emerging Compounders | B18: E1 | C18: History | D18: >= 4 years of data | E18: Data | F18: No investor source: you need a few years of numbers before growth and margin trends can be measured at all. | G18: Makes trend rules meaningful. | H18: Easy
A19: Emerging Compounders | B19: E2 | C19: Recent report | D19: Last annual report <= 1.6 years old | E19: Data | F19: No investor source: a data-quality rule, because old annual numbers can hide a recent collapse. | G19: Keeps the screen current. | H19: Easy | I19: Rare: some foreign (20-F) reports filed but not yet in SEC XBRL data -> flagged.
A20: Emerging Compounders | B20: E3 | C20: Already profitable | D20: TTM and last-FY EBITDA > 0 | E20: Quality | F20: Connor Haley states that already having positive EBITDA means the company is a proven business, not a cash burner, because most big winners were past the profit turning point and were not losing money and diluting shareholders to survive. A mentioned example: in Alta Fox's study of 104 multibaggers (2015-2020), 88% already had positive EBITDA five years earlier. | G20: Cuts cash-burning stories. | H20: Easy | I20: Rare: D&A untagged -> EBIT used.
A21: Emerging Compounders | B21: E4 | C21: Fast growth | D21: 3-yr revenue CAGR >= 15% | E21: Growth | F21: Connor Haley states that fast revenue growth means the company has the engine multibaggers need, because the big winners were growth businesses whose rising sales and profits got the market to re-rate them. A mentioned example: in Alta Fox's 104-stock study the median winner grew revenue 21% a year and EBITDA 28%; even the 25th percentile grew revenue 14% a year. | G21: The growth engine. | H21: Easy
A22: Emerging Compounders | B22: E5 | C22: Growth not fading | D22: Latest year-to-date growth >= 8% (else last FY) | E22: Growth | F22: Alex Sacerdote states that growth still running today means the main risk is not playing out, because "the biggest reason people blow up in tech is they miss on revenue". A mentioned example: US electric-car adoption stalled near 10%, so Whale Rock's rating of that S-curve fell from 10 out of 10 to zero and it stopped owning Tesla. | G22: Catches slowdowns early. | H22: Partly | I22: Foreign filers file no quarterly reports -> uses last fiscal year (stale).
A23: Emerging Compounders | B23: E6 | C23: Gross margin | D23: Gross margin >= 35% | E23: Quality | F23: Connor Haley states that a healthy gross margin means there is room for profit to grow faster than sales, because a company needs enough gross profit on each sale before spreading fixed costs can lift its margins. A mentioned example: in Alta Fox's study, the median multibagger had gross margins in the mid-40s% and EBITDA margins just over 10% at the start. | G23: Operating-leverage potential. | H23: Easy | I23: Rare: no gross-profit line (services) -> no data.
A24: Emerging Compounders | B24: E7 | C24: Operating leverage | D24: EBITDA margin up over 3 yrs, or SG&A/revenue down | E24: Quality | F24: Connor Haley states that overhead falling as a share of sales means the company is reaching operating leverage, because costs growing slower than revenue lift margins, which is often when an undiscovered stock gets re-rated. A mentioned example: in Alta Fox's study, the median winner's SG&A fell 416 basis points of revenue and its EBITDA margin rose 753 basis points over five years. Alex Sacerdote states that rising margins on top of fast growth mean earnings can grow much faster than sales, because with S-curve adoption and a rising margin "your earnings don't grow linearly they grow exponentially". A mentioned example: Whale Rock bought Tesla around end-2019 and 2020, when a cheaper Model 3 made electric-car adoption take off. | G24: Proof the model scales. | H24: Easy
A25: Emerging Compounders | B25: E8 | C25: Little dilution | D25: Share count growth <= 3%/yr (3 yrs) | E25: Quality | F25: Connor Haley states that little dilution means growth reaches each existing share, because per-share value matters more than size, and the big winners were funding themselves instead of issuing stock to cover losses. A mentioned example: in Alta Fox's 104-stock study, the winners were proven concepts that were not losing millions and meaningfully diluting shareholders. Chris Davis states that a share count that does not rise means value builds up for each owner, because long-term compounding only reaches holders if the company is not handing out more slices of itself. A mentioned example: his 50-year study found lasting winners such as Exxon and Philip Morris tended to have share counts that did not go up. | G25: Per-share compounding. | H25: Partly | I25: No share history for recent IPOs/spin-offs and some foreign filers (~20 flagged).
A26: Emerging Compounders | B26: E9 | C26: Leverage | D26: Net debt / EBITDA <= 2.5x | E26: Safety | F26: Connor Haley states that modest debt means downside protection, because a strong balance sheet lets a small company get through a shock that could push a levered one toward bankruptcy. A mentioned example: in March 2020 Alta Fox sold a well-run restaurant stock that had just borrowed to buy another business right before COVID. Brian Gaines states that heavy debt turns the equity into "an option bet", because lenders, especially banks, can force a levered company into bankruptcy, so the share price no longer tracks business value. A mentioned example: Movie Gallery, with $1.1 billion of debt on about 30 million shares, which he described as an option bet. | G26: Downside protection. | H26: Easy | I26: Rare: debt in non-standard tags or D&A untagged -> flagged.
A27: Emerging Compounders | B27: E10 | C27: Size (market cap) | D27: Market cap >= $150M | E27: Tradeability | F27: Connor Haley states that a minimum size means avoiding the tiniest stocks, because Alta Fox's preference for high-quality businesses has worked better a bit higher up, where it has done much better in small, mid and large caps. A mentioned example: Alta Fox's worst market-cap bucket since inception has been micro caps, and its multibagger study only counted companies above $150M. | G27: Micro caps were the study's worst bucket. | H27: Partly | I27: Price x SEC share count. Unreliable for ADRs (ADR ratio unknown), multi-class shares or missing share counts -> 'check manually' (~150 ADRs last run).
A28: Emerging Compounders | B28: E11 | C28: Not already large | D28: Market cap <= $10B | E28: Size | F28: Connor Haley states that staying below about $10B means the company still has room to multiply, because Alta Fox likes small caps that grow into mid caps and mid caps that grow into large caps, and that growth drives the return. A mentioned example: Alta Fox's study of 104 multibaggers only looked at companies with market caps between $150M and $10B. | G28: Runway for a multibagger. | H28: Partly | I28: Price x SEC share count. Unreliable for ADRs (ADR ratio unknown), multi-class shares or missing share counts -> 'check manually' (~150 ADRs last run).
A29: Emerging Compounders | B29: E12 | C29: Valuation | D29: EV / EBITDA <= 20x | E29: Valuation | F29: Connor Haley states that a moderate EV/EBITDA means the thesis can work on profit growth alone, because "if your entire thesis rests on significant multiple expansion maybe it's not a great thesis". A mentioned example: in his study the median multibagger traded about 10x forward EBITDA five years earlier and re-rated to about 25x, with two-thirds of the return from multiple expansion. Chris Davis states that a reasonable starting multiple means your return is set by the business, because he assumes no re-rating: "We may get it, but it's nowhere in our models." A mentioned example: in 2026 his holdings at about 14x earnings offered a 7.5% earnings yield, versus about 3.8% for the market at 26x. | G29: Return comes from growth, not multiple expansion. | H29: Partly | I29: Price x SEC share count. Unreliable for ADRs (ADR ratio unknown), multi-class shares or missing share counts -> 'check manually' (~150 ADRs last run).
A30: Emerging Compounders | B30: E13 | C30: Liquidity | D30: Avg daily value traded >= $200k | E30: Tradeability | F30: Connor Haley states that trading of at least $200k a day means a stock is "reasonably liquid" for a small and micro cap investor, because a fund has to be able to build and exit a real position. A mentioned example: Alta Fox's 104-multibagger study used average daily value traded over $200k as an entry filter. | G30: Tradeable. | H30: Easy
A31: Emerging Compounders | B31: J | C31: Human / AI review | D31: Why overlooked, niche dominance, customer concentration (~70% = kill), insider stake >= 5%, acquisition-led growth | E31: Judgment | F31: Connor Haley states that the questions numbers miss decide the case, because "why might this stock be mispriced" is the key question, 70% customer concentration is a risk that never goes away, and small-cap managers should own at least about 5%. A mentioned example: XPEL, a focused niche leader that competes with far bigger 3M, which he says a focused player can often out-innovate. Pat Dorsey states that moat strength needs human research, because "you can't screen for switching costs"; you have to talk to customers and others who know the business. No specific past example given. | G31: Decides whether the numbers reflect a real thesis. | H31: No | I31: Qualitative; not in financial data. Left to the AI review + you.
A32: Special Situations | B32: U | C32: Universe (event) | D32: Spin-off (Form 10), bankruptcy (8-K item 1.03) or IPO (S-1/F-1) in last 36 months; no funds/banks/insurers | E32: Trigger | F32: Joel Greenblatt states that spin-offs and post-bankruptcy stocks mean likely mispricing, because analysts stop covering a messy company "until the smoke is cleared", and lenders handed shares in a bankruptcy usually sell them. A mentioned example: his Sears stub, bought for about $5 in 1993, reached $30 in two months. Connor Haley states that spin-offs, post-bankruptcy firms and recent IPOs mean a possible edge, because the market has not had long to analyze them, so they can stay mispriced. No specific past example given. | G32: The source of the edge. | H32: Partly | I32: Spin-offs without a Form 10 (e.g. foreign) can be missed; 8-K 1.03 dates the filing, not the emergence.
A33: Special Situations | B33: S1 | C33: Recent report | D33: Last annual report <= 1.6 years old | E33: Data | F33: No investor source: a data-quality rule, because you need current filed numbers to judge the business. | G33: Keeps the screen current. | H33: Partly | I33: New listings often have no annual report yet (only Form 10/prospectus) -> no data.
A34: Special Situations | B34: S2 | C34: Profitable business | D34: TTM operating income > 0 | E34: Quality | F34: Joel Greenblatt states that real operating profit means you can judge whether the business is both good and cheap, because he measures stocks on EBIT against enterprise value and against capital, looking for high returns bought at a high earnings yield. A mentioned example: NII Holdings, a post-bankruptcy wireless business at 2.8x EBITDA, went from $10 to $240 split-adjusted. | G34: Avoids broken companies. | H34: Partly | I34: New listings often lack tagged history -> no data.
A35: Special Situations | B35: S3 | C35: Leverage | D35: Net debt / EBITDA <= 4x | E35: Safety | F35: Brian Gaines states that heavy debt turns the equity into "an option bet", because the capital structure decides whether a company can be pushed into bankruptcy: banks can force it, while fixed-rate bondholders cannot. A mentioned example: Movie Gallery, with $1.1 billion of debt on about 30 million shares, which he said had become an option bet whose share price meant little. | G35: Equity isn't an option bet. | H35: Easy | I35: Rare: debt in non-standard tags or D&A untagged -> flagged.
A36: Special Situations | B36: S4 | C36: Cheap | D36: EV / EBIT <= 15x | E36: Valuation | F36: Joel Greenblatt states that a low EV/EBIT means you are paid well for the risk, because he thinks in pre-tax multiples against a bond yield of at least 6%: about 10x EBIT is similar to that yield, and 12x needs real certainty. A mentioned example: he warned students who put 12x EBIT on their write-ups that only a pretty good business deserves it. | G36: Margin of safety on the mispricing. | H36: Partly | I36: Price x SEC share count. Unreliable for ADRs (ADR ratio unknown), multi-class shares or missing share counts -> 'check manually' (~150 ADRs last run). New listings may lack a share count.
A37: Special Situations | B37: S5 | C37: Size (market cap) | D37: Market cap >= $100M | E37: Tradeability | F37: No investor source: a tradeability rule, because very small companies are hard to buy without moving the price. | G37: Tradeable size. | H37: Partly | I37: Price x SEC share count. Unreliable for ADRs (ADR ratio unknown), multi-class shares or missing share counts -> 'check manually' (~150 ADRs last run).
A38: Special Situations | B38: S6 | C38: Liquidity | D38: Avg daily value traded >= $200k | E38: Tradeability | F38: No investor source: a tradeability rule, because you must be able to get in and out of the stock. | G38: Tradeable. | H38: Easy
A39: Special Situations | B39: J | C39: Human / AI review | D39: Why the parent spins it off, who must sell, management incentives, debt loaded on the spinco, hidden assets | E39: Judgment | F39: Joel Greenblatt states that you must read why the parent is acting and how managers are paid, because many spin-offs come from a position of weakness, and stock owned versus yearly pay is the main thing he checks on management. A mentioned example: when Sears said it had no intention of disposing of Allstate, he read it as a sign it would. Brian Gaines states that insiders putting more money in means the business is not falling apart, because they know more than outsiders do. A mentioned example: Hollywood Video's CEO Mark Wattles rolled his stake into a buyout, going from about 10% to 50% ownership. Chris Davis states that hidden assets and senior claims change the real price, because you should value the whole company like a buyer, counting debt and pensions and assets carried below value. No specific past example given. | G39: Decides whether the numbers reflect a real thesis. | H39: No | I39: Needs reading the Form 10 / reorganization plan.
A40: Fortress | B40: U | C40: Universe | D40: Same as Core | E40: Universe | F40: Chris Hohn states that leaving out banks, airlines, wireless telecom, media and ad agencies means avoiding what he calls bad businesses, because they face heavy competition or, for banks, high leverage, so profits are fragile. A mentioned example: air travel grew about 5% a year for a century, yet airlines collectively made minimal profits. Pat Dorsey states that excluding industries like airlines, auto parts, life insurance and oil and gas means avoiding price takers, because a large part of their future is not under their control. No specific past example given. Terry Smith states that dropping low-return sectors makes sense because good-company sectors don't become bad ones and vice versa; low-return industries stay low. A mentioned example: the airline industry, which he says never makes an adequate return on capital. | G40: Same as Core. | H40: Easy | I40: Uses SEC industry (SIC) code; codes can be coarse or outdated (manual override list exists).
...

Sheet Valuation
A1: Screen | B1: 'Cheap enough' rule (pass/fail) | C1: Kind | D1: Vs peers | E1: Vs own history | F1: Implied return / DCF
A2: Core Compounders | B2: None (price-blind) | C2: - | D2: Shown on site (industry median, green/red); not a rule | E2: No | F2: No
A3: Emerging Compounders | B3: EV/EBITDA <= 20x | C3: Absolute multiple | D3: Shown on site (industry median, green/red); not a rule | E3: No | F3: No
A4: Special Situations | B4: EV/EBIT <= 15x | C4: Absolute multiple | D4: Shown on site (industry median, green/red); not a rule | E4: No | F4: No
A5: Fortress | B5: None (price-blind) | C5: - | D5: Shown on site (industry median, green/red); not a rule | E5: No | F5: No
A6: Healthcare - Commercial | B6: None (price-blind) | C6: - | D6: Shown on site (industry median, green/red); not a rule | E6: No | F6: No
A7: Healthcare - Clinical | B7: EV/cash <= 0.25 | C7: Asset floor | D7: Shown on site (industry median, green/red); not a rule | E7: No | F7: No
A8: Cyclicals | B8: EV / 10-yr avg EBIT <= 12x | C8: Absolute, on normalized earnings | D8: Shown on site (industry median, green/red); not a rule | E8: No | F8: No
A9: Owner-Operators | B9: EV/EBIT <= 20x | C9: Absolute multiple | D9: Shown on site (industry median, green/red); not a rule | E9: No | F9: No
A10: Hard Assets & Royalties | B10: EV/EBIT <= 25x | C10: Absolute multiple | D10: Shown on site (industry median, green/red); not a rule | E10: No | F10: No
A11: Asset-Floor Value | B11: Mcap <= net cash, or P/TBV <= 1.0x | C11: Asset floor | D11: Shown on site (industry median, green/red); not a rule | E11: No | F11: No
A12: Trough Cyclical Cash | B12: 5-yr avg FCF yield >= 10% | C12: Absolute, on cycle-average cash | D12: Shown on site (industry median, green/red); not a rule | E12: No | F12: No
... A14: Red Flags (avoid) | B14: EV/sales >= 6x (expensive = flag) | C14: Absolute multiple | D14: Shown on site (industry median, green/red); not a rule | E14: No | F14: No
A16: Answer: 9 of 13 screens have an absolute 'cheap enough' rule. None compares price to peers or to the company's own past multiples as a pass/fail rule.
A17: Core, Fortress and HC Commercial are price-blind by design: they show P/E, EV/EBITDA, FCF yield and peer medians, but never exclude on price.
A18: Possible adds: (1) peer-relative rule, e.g. EV/EBIT <= industry median (data already computed); (2) FCF-yield hurdle for Core/Fortress/HC; (3) own 5-10 yr multiple percentile (needs multi-year price history, not stored now).

Sheet Summary
A1: Screen | B1: Easy | C1: Partly | D1: No | E1: n/a | F1: Total | G1: % Easy
A2: Core Compounders | B2: =COUNTIFS(Criteria!$A$2:$A$158,$A2,Criteria!$H$2:$H$158,"Easy") -> 10 | C2: =COUNTIFS(Criteria!$A$2:$A$158,$A2,Criteria!$H$2:$H$158,"Partly") -> 0 | D2: =COUNTIFS(Criteria!$A$2:$A$158,$A2,Criteria!$H$2:$H$158,"No") -> 4 | E2: =COUNTIFS(Criteria!$A$2:$A$158,$A2,Criteria!$H$2:$H$158,"n/a") -> 1 | F2: =SUM(B2:E2) -> 15 | G2: =IF(F2=0,0,B2/F2) -> 0.66666667
A3: Emerging Compounders | B3: =COUNTIFS(Criteria!$A$2:$A$158,$A3,Criteria!$H$2:$H$158,"Easy") -> 9 | C3: =COUNTIFS(Criteria!$A$2:$A$158,$A3,Criteria!$H$2:$H$158,"Partly") -> 5 | D3: =COUNTIFS(Criteria!$A$2:$A$158,$A3,Criteria!$H$2:$H$158,"No") -> 1 | E3: =COUNTIFS(Criteria!$A$2:$A$158,$A3,Criteria!$H$2:$H$158,"n/a") -> 0 | F3: =SUM(B3:E3) -> 15 | G3: =IF(F3=0,0,B3/F3) -> 0.6
A4: Special Situations | B4: =COUNTIFS(Criteria!$A$2:$A$158,$A4,Criteria!$H$2:$H$158,"Easy") -> 2 | C4: =COUNTIFS(Criteria!$A$2:$A$158,$A4,Criteria!$H$2:$H$158,"Partly") -> 5 | D4: =COUNTIFS(Criteria!$A$2:$A$158,$A4,Criteria!$H$2:$H$158,"No") -> 1 | E4: =COUNTIFS(Criteria!$A$2:$A$158,$A4,Criteria!$H$2:$H$158,"n/a") -> 0 | F4: =SUM(B4:E4) -> 8 | G4: =IF(F4=0,0,B4/F4) -> 0.25
A5: Fortress | B5: =COUNTIFS(Criteria!$A$2:$A$158,$A5,Criteria!$H$2:$H$158,"Easy") -> 12 | C5: =COUNTIFS(Criteria!$A$2:$A$158,$A5,Criteria!$H$2:$H$158,"Partly") -> 2 | D5: =COUNTIFS(Criteria!$A$2:$A$158,$A5,Criteria!$H$2:$H$158,"No") -> 2 | E5: =COUNTIFS(Criteria!$A$2:$A$158,$A5,Criteria!$H$2:$H$158,"n/a") -> 1 | F5: =SUM(B5:E5) -> 17 | G5: =IF(F5=0,0,B5/F5) -> 0.70588235
A6: Healthcare - Commercial | B6: =COUNTIFS(Criteria!$A$2:$A$158,$A6,Criteria!$H$2:$H$158,"Easy") -> 10 | C6: =COUNTIFS(Criteria!$A$2:$A$158,$A6,Criteria!$H$2:$H$158,"Partly") -> 0 | D6: =COUNTIFS(Criteria!$A$2:$A$158,$A6,Criteria!$H$2:$H$158,"No") -> 2 | E6: =COUNTIFS(Criteria!$A$2:$A$158,$A6,Criteria!$H$2:$H$158,"n/a") -> 1 | F6: =SUM(B6:E6) -> 13 | G6: =IF(F6=0,0,B6/F6) -> 0.76923077
A7: Healthcare - Clinical | B7: =COUNTIFS(Criteria!$A$2:$A$158,$A7,Criteria!$H$2:$H$158,"Easy") -> 5 | C7: =COUNTIFS(Criteria!$A$2:$A$158,$A7,Criteria!$H$2:$H$158,"Partly") -> 2 | D7: =COUNTIFS(Criteria!$A$2:$A$158,$A7,Criteria!$H$2:$H$158,"No") -> 1 | E7: =COUNTIFS(Criteria!$A$2:$A$158,$A7,Criteria!$H$2:$H$158,"n/a") -> 0 | F7: =SUM(B7:E7) -> 8 | G7: =IF(F7=0,0,B7/F7) -> 0.625
A8: Cyclicals | B8: =COUNTIFS(Criteria!$A$2:$A$158,$A8,Criteria!$H$2:$H$158,"Easy") -> 8 | C8: =COUNTIFS(Criteria!$A$2:$A$158,$A8,Criteria!$H$2:$H$158,"Partly") -> 1 | D8: =COUNTIFS(Criteria!$A$2:$A$158,$A8,Criteria!$H$2:$H$158,"No") -> 1 | E8: =COUNTIFS(Criteria!$A$2:$A$158,$A8,Criteria!$H$2:$H$158,"n/a") -> 0 | F8: =SUM(B8:E8) -> 10 | G8: =IF(F8=0,0,B8/F8) -> 0.8
A9: Owner-Operators | B9: =COUNTIFS(Criteria!$A$2:$A$158,$A9,Criteria!$H$2:$H$158,"Easy") -> 9 | C9: =COUNTIFS(Criteria!$A$2:$A$158,$A9,Criteria!$H$2:$H$158,"Partly") -> 3 | D9: =COUNTIFS(Criteria!$A$2:$A$158,$A9,Criteria!$H$2:$H$158,"No") -> 2 | E9: =COUNTIFS(Criteria!$A$2:$A$158,$A9,Criteria!$H$2:$H$158,"n/a") -> 0 | F9: =SUM(B9:E9) -> 14 | G9: =IF(F9=0,0,B9/F9) -> 0.64285714
A10: Hard Assets & Royalties | B10: =COUNTIFS(Criteria!$A$2:$A$158,$A10,Criteria!$H$2:$H$158,"Easy") -> 9 | C10: =COUNTIFS(Criteria!$A$2:$A$158,$A10,Criteria!$H$2:$H$158,"Partly") -> 2 | D10: =COUNTIFS(Criteria!$A$2:$A$158,$A10,Criteria!$H$2:$H$158,"No") -> 1 | E10: =COUNTIFS(Criteria!$A$2:$A$158,$A10,Criteria!$H$2:$H$158,"n/a") -> 0 | F10: =SUM(B10:E10) -> 12 | G10: =IF(F10=0,0,B10/F10) -> 0.75
A11: Asset-Floor Value | B11: =COUNTIFS(Criteria!$A$2:$A$158,$A11,Criteria!$H$2:$H$158,"Easy") -> 8 | C11: =COUNTIFS(Criteria!$A$2:$A$158,$A11,Criteria!$H$2:$H$158,"Partly") -> 2 | D11: =COUNTIFS(Criteria!$A$2:$A$158,$A11,Criteria!$H$2:$H$158,"No") -> 1 | E11: =COUNTIFS(Criteria!$A$2:$A$158,$A11,Criteria!$H$2:$H$158,"n/a") -> 0 | F11: =SUM(B11:E11) -> 11 | G11: =IF(F11=0,0,B11/F11) -> 0.72727273
A12: Trough Cyclical Cash | B12: =COUNTIFS(Criteria!$A$2:$A$158,$A12,Criteria!$H$2:$H$158,"Easy") -> 7 | C12: =COUNTIFS(Criteria!$A$2:$A$158,$A12,Criteria!$H$2:$H$158,"Partly") -> 5 | D12: =COUNTIFS(Criteria!$A$2:$A$158,$A12,Criteria!$H$2:$H$158,"No") -> 1 | E12: =COUNTIFS(Criteria!$A$2:$A$158,$A12,Criteria!$H$2:$H$158,"n/a") -> 0 | F12: =SUM(B12:E12) -> 13 | G12: =IF(F12=0,0,B12/F12) -> 0.53846154
A13: Hidden Earnings | B13: =COUNTIFS(Criteria!$A$2:$A$158,$A13,Criteria!$H$2:$H$158,"Easy") -> 9 | C13: =COUNTIFS(Criteria!$A$2:$A$158,$A13,Criteria!$H$2:$H$158,"Partly") -> 3 | D13: =COUNTIFS(Criteria!$A$2:$A$158,$A13,Criteria!$H$2:$H$158,"No") -> 1 | E13: =COUNTIFS(Criteria!$A$2:$A$158,$A13,Criteria!$H$2:$H$158,"n/a") -> 0 | F13: =SUM(B13:E13) -> 13 | G13: =IF(F13=0,0,B13/F13) -> 0.69230769
A14: Red Flags (avoid) | B14: =COUNTIFS(Criteria!$A$2:$A$158,$A14,Criteria!$H$2:$H$158,"Easy") -> 4 | C14: =COUNTIFS(Criteria!$A$2:$A$158,$A14,Criteria!$H$2:$H$158,"Partly") -> 3 | D14: =COUNTIFS(Criteria!$A$2:$A$158,$A14,Criteria!$H$2:$H$158,"No") -> 1 | E14: =COUNTIFS(Criteria!$A$2:$A$158,$A14,Criteria!$H$2:$H$158,"n/a") -> 0 | F14: =SUM(B14:E14) -> 8 | G14: =IF(F14=0,0,B14/F14) -> 0.5
A15: All screens | B15: =SUM(B2:B14) -> 102 | C15: =SUM(C2:C14) -> 33 | D15: =SUM(D2:D14) -> 19 | E15: =SUM(E2:E14) -> 3 | F15: =SUM(F2:F14) -> 157 | G15: =IF(F15=0,0,B15/F15) -> 0.64968153
A17: Legend
A18: Easy | B18: Checked automatically from SEC XBRL / price data and reliable for nearly all companies; rare exceptions are auto-flagged.
A19: Partly | B19: Automatic for most, but a known group (ADRs, multi-class shares, foreign filers, untagged items) lands in 'check manually'.
A20: No | B20: Not checked by numbers: warning flags or judgment items for the AI review + you.
A21: n/a | B21: No rule (price-blind screens).
A22: Rationale | B22: Format: investor states that X means Y, because Z; example. Checked against all 146 transcripts. 'No investor source' = practical data rule.
A23: Note | B23: Each row is in config.json; thresholds can be changed there. Counts like '~150' are from the 7 Oct 2026 check-manually report.
